<mujoco model="scout_v2">
  <compiler angle='radian' eulerseq="XYZ" meshdir="./assets"
    autolimits="true" />

  <option timestep="0.001" />

  <default>
      <default class="scout">
          <site rgba="1 0 0 1" size="0.01" group="5"/>
          <joint damping="0.0" armature="0.03" frictionloss="0.3"/>
          <default class="visual">
              <geom group="2" type="mesh" contype="0" conaffinity="0" density="0"/>
          </default>
          <default class="collision">
              <!-- <geom group="3" type="mesh" condim="6" friction="1.2 0.1 0.01" solref="0.015 1.2" solimp="0.9 0.95 0.001"/> --> # 精细摩擦力
              <geom group="3" type="mesh"/>
          </default>
      </default>
  </default>
  <asset>
    <mesh name="base_link" file="base_link.STL"/>
    <mesh name="wheel_type1" file="wheel_type1.STL"/>
    <mesh name="wheel_type2" file="wheel_type2.STL"/>
    <mesh name="scout_upload" file="scout_upload.STL"/>
    <mesh name="lidar16" file="LiDar16.STL"/>
    <mesh name="realsense_d435" file="IntelRealsense_D435.STL"/>
  </asset>

  <worldbody>
    <body name="base_link" pos="0 0 0.23479" euler="0 0 0" childclass="scout">
      <light name="tracking" mode="trackcom" pos="0 0 2"/>
      <freejoint name="floating_base_joint"/>
      <inertial pos="0 0 0" mass="40" diaginertia="2.288641 5.103976 3.431465"/>
      <geom class="visual" type="mesh" contype="0" conaffinity="0" group="1" density="0" rgba="0.298039 0.298039 0.298039 1" mesh="base_link"/>
      <geom class="collision" type="mesh" rgba="0.298039 0.298039 0.298039 1" mesh="base_link"/>
      <camera name="track" pos="-2 0 1.5" xyaxes="0 -1 0 1 0 2" mode="trackcom"/>
      <site name="imu" pos="0 0 0.05" group="3"/>
      <site name="front_mount" pos="0.325 0 0.112701" group="3"/>
      <site name="rear_mount" pos="-0.325 0 0.112701" group="3"/>

      <body name="upload" pos="0.42074 -0.31815 -0.095" euler="1.57079632679 0 3.14159265">
        <geom class="visual" type="mesh" contype="0" conaffinity="0" group="2" density="0"
          rgba="0.298039 0.298039 0.298039 1" mesh="scout_upload"/>
        <geom class="collision" type="mesh" rgba="0.298039 0.298039 0.298039 1" mesh="scout_upload"/>
      </body>

      <body name="sensors" pos="-0.005 -0.045 -0.095" euler="0 0 0">
        <geom class="visual" type="mesh" contype="0" conaffinity="0" group="2" density="0" rgba="0.298039 0.298039 0.298039 1" pos="0 -0.0225 0" mesh="lidar16"/>
        <geom class="visual" type="mesh" contype="0" conaffinity="0" group="2" density="0" rgba="0.298039 0.298039 0.298039 1" mesh="realsense_d435"/>
        <camera name="D435" pos="0.4 0.045 0.415" xyaxes="0 -1 0 0 0 1" focal="1.283 1.285" sensorsize="1.777778 1" resolution="640 360"/>
      </body>

      <body name="front_right_wheel_link" pos="0.249 -0.29153 -0.0702" euler="3.14 0 0">
        <inertial pos="0 0 0" mass="3" diaginertia="0.0439 0.0510 0.0439"/>
        <joint name="front_right_wheel" pos="0 0 0" axis="0 -1 0" actuatorfrcrange="-80 80"/>
        <geom class="visual" type="mesh" contype="0" conaffinity="0" group="1" density="0" rgba="0.02 0.02 0.02 1" mesh="wheel_type1"/>
        <geom class="collision" type="mesh" rgba="0.02 0.02 0.02 1" mesh="wheel_type1"/>
      </body>

      <body name="front_left_wheel_link" pos="0.249 0.29153 -0.0702" euler="0 0 0">
        <inertial pos="0 0 0" mass="3" diaginertia="0.0439 0.0510 0.0439"/>
        <joint name="front_left_wheel" pos="0 0 0" axis="0 -1 0" actuatorfrcrange="-80 80"/>
        <geom class="visual" type="mesh" contype="0" conaffinity="0" group="1" density="0" rgba="0.02 0.02 0.02 1" mesh="wheel_type2"/>
        <geom class="collision" type="mesh" rgba="0.02 0.02 0.02 1" mesh="wheel_type2"/>
      </body>

      <body name="rear_left_wheel_link" pos="-0.249 0.29153 -0.0702" euler="0 0 0">
        <inertial pos="0 0 0" mass="3" diaginertia="0.0439 0.0510 0.0439"/>
        <joint name="rear_left_wheel" pos="0 0 0" axis="0 -1 0" actuatorfrcrange="-80 80"/>
        <geom class="visual" type="mesh" contype="0" conaffinity="0" group="1" density="0" rgba="0.02 0.02 0.02 1" mesh="wheel_type1"/>
        <geom class="collision" type="mesh" rgba="0.02 0.02 0.02 1" mesh="wheel_type1"/>
      </body>

      <body name="rear_right_wheel_link" pos="-0.249 -0.29153 -0.0702" euler="3.14 0 0">
        <inertial pos="0 0 0" mass="3" diaginertia="0.0439 0.0510 0.0439"/>
        <joint name="rear_right_wheel" pos="0 0 0" axis="0 -1 0" actuatorfrcrange="-80 80"/>
        <geom class="visual" type="mesh" contype="0" conaffinity="0" group="1" density="0" rgba="0.02 0.02 0.02 1" mesh="wheel_type2"/>
        <geom class="collision" type="mesh" rgba="0.02 0.02 0.02 1" mesh="wheel_type2"/>
      </body>
    </body>
  </worldbody>
  <actuator>
    <velocity class="scout" name="velocity_front_right_wheel" joint="front_right_wheel" kv="100" ctrlrange="-20 20"/>
    <velocity class="scout" name="velocity_front_left_wheel" joint="front_left_wheel" kv="100" ctrlrange="-20 20"/>
    <velocity class="scout" name="velocity_rear_left_wheel" joint="rear_left_wheel" kv="100" ctrlrange="-20 20"/>
    <velocity class="scout" name="velocity_rear_right_wheel" joint="rear_right_wheel" kv="100" ctrlrange="-20 20"/>
  </actuator>
  <sensor>
    <gyro name="body_gyro" site="imu"/>
    <accelerometer name="body_linacc" site="imu"/>
    <framequat name="body_quat" objtype="site" objname="imu"/>
  </sensor>
</mujoco>
